2024-07-16 07:00:12,126 - run_b5da05af-94e0-43af-b590-dbccbb52bf9a - INFO - Span: Step :transcribe
2024-07-16 07:00:12,127 - run_b5da05af-94e0-43af-b590-dbccbb52bf9a - INFO -   Trace ID: 214966684065760430275386986360746154885
2024-07-16 07:00:12,127 - run_b5da05af-94e0-43af-b590-dbccbb52bf9a - INFO -   Span ID: 5956250985259364771
2024-07-16 07:00:12,128 - run_b5da05af-94e0-43af-b590-dbccbb52bf9a - INFO -   Parent ID: 129931871149079736
2024-07-16 07:00:12,128 - run_b5da05af-94e0-43af-b590-dbccbb52bf9a - INFO -   Start time: 2024-07-16 07:00:12.114
2024-07-16 07:00:12,128 - run_b5da05af-94e0-43af-b590-dbccbb52bf9a - INFO -   End time: 2024-07-16 07:00:12.124
2024-07-16 07:00:12,129 - run_b5da05af-94e0-43af-b590-dbccbb52bf9a - INFO -   Duration: 0.010s
2024-07-16 07:00:12,129 - run_b5da05af-94e0-43af-b590-dbccbb52bf9a - INFO -   Attributes:
2024-07-16 07:00:12,129 - run_b5da05af-94e0-43af-b590-dbccbb52bf9a - INFO -     run_id: b5da05af-94e0-43af-b590-dbccbb52bf9a
2024-07-16 07:00:12,129 - run_b5da05af-94e0-43af-b590-dbccbb52bf9a - INFO -     input_name: first_args
2024-07-16 07:00:12,136 - run_b5da05af-94e0-43af-b590-dbccbb52bf9a - INFO -     function: transcribe_empty
2024-07-16 07:00:12,136 - run_b5da05af-94e0-43af-b590-dbccbb52bf9a - INFO -   Events:
2024-07-16 07:00:12,136 - run_b5da05af-94e0-43af-b590-dbccbb52bf9a - INFO -     exception at 2024-07-16 07:00:12.124 (+0.010s):
2024-07-16 07:00:12,136 - run_b5da05af-94e0-43af-b590-dbccbb52bf9a - INFO -       exception.type: UnboundLocalError
2024-07-16 07:00:12,136 - run_b5da05af-94e0-43af-b590-dbccbb52bf9a - INFO -       exception.message: cannot access local variable 'tracer' where it is not associated with a value
2024-07-16 07:00:12,136 - run_b5da05af-94e0-43af-b590-dbccbb52bf9a - INFO -       exception.stacktrace: Traceback (most recent call last):
  File "/Users/chrysostomebeltran/Downloads/exercise/.venv/lib/python3.12/site-packages/opentelemetry/trace/__init__.py", line 570, in use_span
    yield span
  File "/Users/chrysostomebeltran/Downloads/exercise/.venv/lib/python3.12/site-packages/opentelemetry/sdk/trace/__init__.py", line 1091, in start_as_current_span
    yield span
  File "/Users/chrysostomebeltran/Downloads/exercise/workflows/pipeline.py", line 466, in run
    self._output = await asyncio.to_thread(self.f, *args, **kwargs)
                   ^^^^^^^^^^^^^^^^^^^^^^^^^^^^^^^^^^^^^^^^^^^^^^^^
  File "/Users/chrysostomebeltran/anaconda3/envs/gitverse/lib/python3.12/asyncio/threads.py", line 25, in to_thread
    return await loop.run_in_executor(None, func_call)
           ^^^^^^^^^^^^^^^^^^^^^^^^^^^^^^^^^^^^^^^^^^^
  File "/Users/chrysostomebeltran/anaconda3/envs/gitverse/lib/python3.12/concurrent/futures/thread.py", line 58, in run
    result = self.fn(*self.args, **self.kwargs)
             ^^^^^^^^^^^^^^^^^^^^^^^^^^^^^^^^^^
  File "/Users/chrysostomebeltran/Downloads/exercise/workflows/pipeline.py", line 358, in wrapper
    span = tracer.get_current_span()
           ^^^^^^
UnboundLocalError: cannot access local variable 'tracer' where it is not associated with a value

2024-07-16 07:00:12,147 - run_b5da05af-94e0-43af-b590-dbccbb52bf9a - INFO -       exception.escaped: False
2024-07-16 07:00:12,148 - run_b5da05af-94e0-43af-b590-dbccbb52bf9a - INFO - 
2024-07-16 07:00:12,149 - run_b5da05af-94e0-43af-b590-dbccbb52bf9a - INFO - Span: Pipeline :pipe
2024-07-16 07:00:12,149 - run_b5da05af-94e0-43af-b590-dbccbb52bf9a - INFO -   Trace ID: 214966684065760430275386986360746154885
2024-07-16 07:00:12,149 - run_b5da05af-94e0-43af-b590-dbccbb52bf9a - INFO -   Span ID: 129931871149079736
2024-07-16 07:00:12,149 - run_b5da05af-94e0-43af-b590-dbccbb52bf9a - INFO -   Parent ID: None
2024-07-16 07:00:12,149 - run_b5da05af-94e0-43af-b590-dbccbb52bf9a - INFO -   Start time: 2024-07-16 07:00:12.114
2024-07-16 07:00:12,149 - run_b5da05af-94e0-43af-b590-dbccbb52bf9a - INFO -   End time: 2024-07-16 07:00:12.149
2024-07-16 07:00:12,149 - run_b5da05af-94e0-43af-b590-dbccbb52bf9a - INFO -   Duration: 0.035s
2024-07-16 07:00:12,149 - run_b5da05af-94e0-43af-b590-dbccbb52bf9a - INFO -   Attributes:
2024-07-16 07:00:12,149 - run_b5da05af-94e0-43af-b590-dbccbb52bf9a - INFO -     run_id: b5da05af-94e0-43af-b590-dbccbb52bf9a
2024-07-16 07:00:12,149 - run_b5da05af-94e0-43af-b590-dbccbb52bf9a - INFO -   Events:
2024-07-16 07:00:12,150 - run_b5da05af-94e0-43af-b590-dbccbb52bf9a - INFO -     exception at 2024-07-16 07:00:12.148 (+0.034s):
2024-07-16 07:00:12,150 - run_b5da05af-94e0-43af-b590-dbccbb52bf9a - INFO -       exception.type: UnboundLocalError
2024-07-16 07:00:12,150 - run_b5da05af-94e0-43af-b590-dbccbb52bf9a - INFO -       exception.message: cannot access local variable 'tracer' where it is not associated with a value
2024-07-16 07:00:12,150 - run_b5da05af-94e0-43af-b590-dbccbb52bf9a - INFO -       exception.stacktrace: Traceback (most recent call last):
  File "/Users/chrysostomebeltran/Downloads/exercise/workflows/pipeline.py", line 240, in start
    result = await self.run(input, run_id)
             ^^^^^^^^^^^^^^^^^^^^^^^^^^^^^
  File "/Users/chrysostomebeltran/Downloads/exercise/workflows/pipeline.py", line 266, in run
    result = await child.run(input, child.input_name, run_id)
             ^^^^^^^^^^^^^^^^^^^^^^^^^^^^^^^^^^^^^^^^^^^^^^^^
  File "/Users/chrysostomebeltran/Downloads/exercise/workflows/pipeline.py", line 466, in run
    self._output = await asyncio.to_thread(self.f, *args, **kwargs)
                   ^^^^^^^^^^^^^^^^^^^^^^^^^^^^^^^^^^^^^^^^^^^^^^^^
  File "/Users/chrysostomebeltran/anaconda3/envs/gitverse/lib/python3.12/asyncio/threads.py", line 25, in to_thread
    return await loop.run_in_executor(None, func_call)
           ^^^^^^^^^^^^^^^^^^^^^^^^^^^^^^^^^^^^^^^^^^^
  File "/Users/chrysostomebeltran/anaconda3/envs/gitverse/lib/python3.12/concurrent/futures/thread.py", line 58, in run
    result = self.fn(*self.args, **self.kwargs)
             ^^^^^^^^^^^^^^^^^^^^^^^^^^^^^^^^^^
  File "/Users/chrysostomebeltran/Downloads/exercise/workflows/pipeline.py", line 358, in wrapper
    span = tracer.get_current_span()
           ^^^^^^
UnboundLocalError: cannot access local variable 'tracer' where it is not associated with a value

2024-07-16 07:00:12,150 - run_b5da05af-94e0-43af-b590-dbccbb52bf9a - INFO -       exception.escaped: False
2024-07-16 07:00:12,150 - run_b5da05af-94e0-43af-b590-dbccbb52bf9a - INFO -     Pipeline : pipe execution completed at 2024-07-16 07:00:12.148 (+0.034s):
2024-07-16 07:00:12,150 - run_b5da05af-94e0-43af-b590-dbccbb52bf9a - INFO -     No output due to exception at 2024-07-16 07:00:12.148 (+0.034s):
2024-07-16 07:00:12,150 - run_b5da05af-94e0-43af-b590-dbccbb52bf9a - INFO -     exception at 2024-07-16 07:00:12.149 (+0.035s):
2024-07-16 07:00:12,150 - run_b5da05af-94e0-43af-b590-dbccbb52bf9a - INFO -       exception.type: UnboundLocalError
2024-07-16 07:00:12,150 - run_b5da05af-94e0-43af-b590-dbccbb52bf9a - INFO -       exception.message: cannot access local variable 'tracer' where it is not associated with a value
2024-07-16 07:00:12,150 - run_b5da05af-94e0-43af-b590-dbccbb52bf9a - INFO -       exception.stacktrace: Traceback (most recent call last):
  File "/Users/chrysostomebeltran/Downloads/exercise/.venv/lib/python3.12/site-packages/opentelemetry/trace/__init__.py", line 570, in use_span
    yield span
  File "/Users/chrysostomebeltran/Downloads/exercise/.venv/lib/python3.12/site-packages/opentelemetry/sdk/trace/__init__.py", line 1091, in start_as_current_span
    yield span
  File "/Users/chrysostomebeltran/Downloads/exercise/workflows/pipeline.py", line 240, in start
    result = await self.run(input, run_id)
             ^^^^^^^^^^^^^^^^^^^^^^^^^^^^^
  File "/Users/chrysostomebeltran/Downloads/exercise/workflows/pipeline.py", line 266, in run
    result = await child.run(input, child.input_name, run_id)
             ^^^^^^^^^^^^^^^^^^^^^^^^^^^^^^^^^^^^^^^^^^^^^^^^
  File "/Users/chrysostomebeltran/Downloads/exercise/workflows/pipeline.py", line 466, in run
    self._output = await asyncio.to_thread(self.f, *args, **kwargs)
                   ^^^^^^^^^^^^^^^^^^^^^^^^^^^^^^^^^^^^^^^^^^^^^^^^
  File "/Users/chrysostomebeltran/anaconda3/envs/gitverse/lib/python3.12/asyncio/threads.py", line 25, in to_thread
    return await loop.run_in_executor(None, func_call)
           ^^^^^^^^^^^^^^^^^^^^^^^^^^^^^^^^^^^^^^^^^^^
  File "/Users/chrysostomebeltran/anaconda3/envs/gitverse/lib/python3.12/concurrent/futures/thread.py", line 58, in run
    result = self.fn(*self.args, **self.kwargs)
             ^^^^^^^^^^^^^^^^^^^^^^^^^^^^^^^^^^
  File "/Users/chrysostomebeltran/Downloads/exercise/workflows/pipeline.py", line 358, in wrapper
    span = tracer.get_current_span()
           ^^^^^^
UnboundLocalError: cannot access local variable 'tracer' where it is not associated with a value

2024-07-16 07:00:12,150 - run_b5da05af-94e0-43af-b590-dbccbb52bf9a - INFO -       exception.escaped: False
2024-07-16 07:00:12,150 - run_b5da05af-94e0-43af-b590-dbccbb52bf9a - INFO - 
